<mujoco model="two finger gripper">
  <compiler angle="radian"/>
  <option timestep="0.002" gravity="0 0 -9.81"/>

  <default>
    <geom friction="1.2 0.01 0.001" condim="4"/>
    <joint damping="1"/>
  </default>

  <worldbody>
    <light pos="0.5 -0.5 1.5"/>
    <geom name="floor" type="plane" size="2 2 0.1" rgba="0.8 0.8 0.8 1"/>

    <body name="object" pos="0 0 0.025">
      <freejoint name="object_free_joint"/>
      <geom name="object_geom"
            type="box"
            size="0.025 0.025 0.025"
            mass="0.08"
            rgba="0.2 0.7 0.3 1"/>
    </body>

    <body name="hand" pos="0 0 0">
      <joint name="hand_lift"
             type="slide"
             axis="0 0 1"
             range="0 0.2"/>

      <geom name="palm_geom"
            type="box"
            pos="0 0 0.10"
            size="0.06 0.06 0.01"
            mass="1"
            rgba="0.3 0.3 0.35 1"/>

      <body name="left_finger" pos="0 0.07 0.045">
        <joint name="left_finger_joint"
               type="slide"
               axis="0 -1 0"
               range="0 0.045"/>
        <geom name="left_finger_geom"
              type="box"
              size="0.035 0.01 0.045"
              mass="0.1"
              rgba="0.9 0.4 0.2 1"/>
      </body>

      <body name="right_finger" pos="0 -0.07 0.045">
        <joint name="right_finger_joint"
               type="slide"
               axis="0 1 0"
               range="0 0.045"/>
        <geom name="right_finger_geom"
              type="box"
              size="0.035 0.01 0.045"
              mass="0.1"
              rgba="0.2 0.4 0.9 1"/>
      </body>
    </body>
  </worldbody>

  <actuator>
    <position name="lift_actuator"
              joint="hand_lift"
              kp="500"
              kv="30"
              ctrlrange="0 0.2"/>
    <position name="left_finger_actuator"
              joint="left_finger_joint"
              kp="120"
              kv="5"
              ctrlrange="0 0.045"/>
    <position name="right_finger_actuator"
              joint="right_finger_joint"
              kp="120"
              kv="5"
              ctrlrange="0 0.045"/>
  </actuator>
</mujoco>
