<mujoco model="single hinge">
  <option timestep="0.002" gravity="0 0 -9.81"/>

  <worldbody>
    <light pos="0 0 2"/>
    <geom name="floor" type="plane" size="2 2 0.1" rgba="0.8 0.8 0.8 1"/>

    <body name="stand" pos="0 0 0.8">
      <geom type="sphere" size="0.04" rgba="0.2 0.2 0.2 1"/>

      <body name="arm">
        <joint name="arm_joint"
               type="hinge"
               axis="0 1 0"
               range="-90 90"
               damping="0.2"/>
        <geom name="arm_geom"
              type="capsule"
              fromto="0 0 0 0 0 -0.5"
              size="0.035"
              mass="0.5"
              rgba="0.9 0.4 0.2 1"/>
      </body>
    </body>
  </worldbody>

  <actuator>
    <position name="arm_position"
              joint="arm_joint"
              kp="30"
              kv="3"
              ctrlrange="-1.57 1.57"/>
  </actuator>
</mujoco>
